I'm sorry, but an uncaught exception occurred.

While running game code:
  File "game/script.rpy", line 65, in script
    peach "Oh hi there! [stats]"
KeyError: u'stats'

-- Full Traceback ------------------------------------------------------------

Full traceback:
  File "game/script.rpy", line 65, in script
    peach "Oh hi there! [stats]"
  File "/Users/James/Desktop/renpy-6.99.14.3-sdk/renpy/ast.py", line 652, in execute
    renpy.exports.say(who, what, interact=self.interact, *args, **kwargs)
  File "/Users/James/Desktop/renpy-6.99.14.3-sdk/renpy/exports.py", line 1180, in say
    who(what, *args, **kwargs)
  File "/Users/James/Desktop/renpy-6.99.14.3-sdk/renpy/character.py", line 1003, in __call__
    what = what_pattern.replace("[what]", sub(what, translate=translate))
  File "/Users/James/Desktop/renpy-6.99.14.3-sdk/renpy/character.py", line 985, in sub
    return renpy.substitutions.substitute(s, scope=scope, force=force, translate=translate)[0]
  File "/Users/James/Desktop/renpy-6.99.14.3-sdk/renpy/substitutions.py", line 242, in substitute
    s = formatter.vformat(s, (), kwargs)
  File "/home/tom/ab/x64lucid-deps/install/lib/python2.7/string.py", line 563, in vformat
  File "/home/tom/ab/x64lucid-deps/install/lib/python2.7/string.py", line 585, in _vformat
  File "/home/tom/ab/x64lucid-deps/install/lib/python2.7/string.py", line 646, in get_field
  File "/home/tom/ab/x64lucid-deps/install/lib/python2.7/string.py", line 605, in get_value
KeyError: u'stats'

Darwin-15.6.0-x86_64-i386-64bit
Ren'Py 6.99.14.3.3347
RenPy 1.0
Tue May 29 18:29:32 2018
